[2020-09-18 16:38:31 +0000] [1] [INFO] Starting gunicorn 20.0.4
[2020-09-18 16:38:31 +0000] [1] [INFO] Listening at: http://0.0.0.0:5000 (1)
[2020-09-18 16:38:31 +0000] [1] [INFO] Using worker: gevent
[2020-09-18 16:38:31 +0000] [7] [INFO] Booting worker with pid: 7
[2020-09-18 16:38:31 +0000] [8] [INFO] Booting worker with pid: 8
[2020-09-18 16:38:31 +0000] [9] [INFO] Booting worker with pid: 9
[2020-09-18 16:38:43 +0000] [1] [INFO] Handling signal: term
[2020-09-18 16:38:49 +0000] [1] [INFO] Starting gunicorn 20.0.4
[2020-09-18 16:38:49 +0000] [1] [INFO] Listening at: http://0.0.0.0:5000 (1)
[2020-09-18 16:38:49 +0000] [1] [INFO] Using worker: gevent
[2020-09-18 16:38:49 +0000] [7] [INFO] Booting worker with pid: 7
[2020-09-18 16:38:49 +0000] [8] [INFO] Booting worker with pid: 8
[2020-09-18 16:38:49 +0000] [9] [INFO] Booting worker with pid: 9
[2020-09-18 17:25:27 +0000] [1] [INFO] Handling signal: term
[2020-09-18 17:25:29 +0000] [1] [INFO] Shutting down: Master
[2020-09-18 17:25:31 +0000] [1] [INFO] Starting gunicorn 20.0.4
[2020-09-18 17:25:31 +0000] [1] [INFO] Listening at: http://0.0.0.0:5000 (1)
[2020-09-18 17:25:31 +0000] [1] [INFO] Using worker: gevent
[2020-09-18 17:25:31 +0000] [7] [INFO] Booting worker with pid: 7
[2020-09-18 17:25:31 +0000] [8] [INFO] Booting worker with pid: 8
[2020-09-18 17:25:31 +0000] [9] [INFO] Booting worker with pid: 9
[2020-09-18 17:25:32 +0000] [1] [INFO] Shutting down: Master
[2020-09-18 17:25:32 +0000] [1] [INFO] Reason: Worker failed to boot.
[2020-09-18 17:25:57 +0000] [1] [INFO] Starting gunicorn 20.0.4
[2020-09-18 17:25:57 +0000] [1] [INFO] Listening at: http://0.0.0.0:5000 (1)
[2020-09-18 17:25:57 +0000] [1] [INFO] Using worker: gevent
[2020-09-18 17:25:57 +0000] [8] [INFO] Booting worker with pid: 8
[2020-09-18 17:25:57 +0000] [9] [INFO] Booting worker with pid: 9
[2020-09-18 17:25:57 +0000] [10] [INFO] Booting worker with pid: 10
Traceback (most recent call last):
  File "/usr/local/lib/python3.8/dist-packages/gunicorn/arbiter.py", line 209, in run
    self.sleep()
  File "/usr/local/lib/python3.8/dist-packages/gunicorn/arbiter.py", line 357, in sleep
    ready = select.select([self.PIPE[0]], [], [], 1.0)
  File "/usr/local/lib/python3.8/dist-packages/gunicorn/arbiter.py", line 242, in handle_chld
    self.reap_workers()
  File "/usr/local/lib/python3.8/dist-packages/gunicorn/arbiter.py", line 525, in reap_workers
    raise HaltServer(reason, self.WORKER_BOOT_ERROR)
gunicorn.errors.HaltServer: <HaltServer 'Worker failed to boot.' 3>

During handling of the above exception, another exception occurred:

Traceback (most recent call last):
  File "/usr/local/bin/gunicorn", line 8, in <module>
    sys.exit(run())
  File "/usr/local/lib/python3.8/dist-packages/gunicorn/app/wsgiapp.py", line 58, in run
    WSGIApplication("%(prog)s [OPTIONS] [APP_MODULE]").run()
  File "/usr/local/lib/python3.8/dist-packages/gunicorn/app/base.py", line 228, in run
    super().run()
  File "/usr/local/lib/python3.8/dist-packages/gunicorn/app/base.py", line 72, in run
    Arbiter(self).run()
  File "/usr/local/lib/python3.8/dist-packages/gunicorn/arbiter.py", line 229, in run
    self.halt(reason=inst.reason, exit_status=inst.exit_status)
  File "/usr/local/lib/python3.8/dist-packages/gunicorn/arbiter.py", line 342, in halt
    self.stop()
  File "/usr/local/lib/python3.8/dist-packages/gunicorn/arbiter.py", line 393, in stop
    time.sleep(0.1)
  File "/usr/local/lib/python3.8/dist-packages/gunicorn/arbiter.py", line 242, in handle_chld
    self.reap_workers()
  File "/usr/local/lib/python3.8/dist-packages/gunicorn/arbiter.py", line 525, in reap_workers
    raise HaltServer(reason, self.WORKER_BOOT_ERROR)
gunicorn.errors.HaltServer: <HaltServer 'Worker failed to boot.' 3>
[2020-09-18 17:40:23 +0000] [1] [INFO] Starting gunicorn 20.0.4
[2020-09-18 17:40:23 +0000] [1] [INFO] Listening at: http://0.0.0.0:5000 (1)
[2020-09-18 17:40:23 +0000] [1] [INFO] Using worker: gevent
[2020-09-18 17:40:23 +0000] [7] [INFO] Booting worker with pid: 7
[2020-09-18 17:40:23 +0000] [8] [INFO] Booting worker with pid: 8
[2020-09-18 17:40:24 +0000] [9] [INFO] Booting worker with pid: 9
Traceback (most recent call last):
  File "/usr/local/lib/python3.8/dist-packages/gunicorn/arbiter.py", line 209, in run
    self.sleep()
  File "/usr/local/lib/python3.8/dist-packages/gunicorn/arbiter.py", line 357, in sleep
    ready = select.select([self.PIPE[0]], [], [], 1.0)
  File "/usr/local/lib/python3.8/dist-packages/gunicorn/arbiter.py", line 242, in handle_chld
    self.reap_workers()
  File "/usr/local/lib/python3.8/dist-packages/gunicorn/arbiter.py", line 525, in reap_workers
    raise HaltServer(reason, self.WORKER_BOOT_ERROR)
gunicorn.errors.HaltServer: <HaltServer 'Worker failed to boot.' 3>

During handling of the above exception, another exception occurred:

Traceback (most recent call last):
  File "/usr/local/bin/gunicorn", line 8, in <module>
    sys.exit(run())
  File "/usr/local/lib/python3.8/dist-packages/gunicorn/app/wsgiapp.py", line 58, in run
    WSGIApplication("%(prog)s [OPTIONS] [APP_MODULE]").run()
  File "/usr/local/lib/python3.8/dist-packages/gunicorn/app/base.py", line 228, in run
    super().run()
  File "/usr/local/lib/python3.8/dist-packages/gunicorn/app/base.py", line 72, in run
    Arbiter(self).run()
  File "/usr/local/lib/python3.8/dist-packages/gunicorn/arbiter.py", line 229, in run
    self.halt(reason=inst.reason, exit_status=inst.exit_status)
  File "/usr/local/lib/python3.8/dist-packages/gunicorn/arbiter.py", line 342, in halt
    self.stop()
  File "/usr/local/lib/python3.8/dist-packages/gunicorn/arbiter.py", line 393, in stop
    time.sleep(0.1)
  File "/usr/local/lib/python3.8/dist-packages/gunicorn/arbiter.py", line 242, in handle_chld
    self.reap_workers()
  File "/usr/local/lib/python3.8/dist-packages/gunicorn/arbiter.py", line 525, in reap_workers
    raise HaltServer(reason, self.WORKER_BOOT_ERROR)
gunicorn.errors.HaltServer: <HaltServer 'Worker failed to boot.' 3>
[2020-09-18 17:40:42 +0000] [1] [INFO] Starting gunicorn 20.0.4
[2020-09-18 17:40:42 +0000] [1] [INFO] Listening at: http://0.0.0.0:5000 (1)
[2020-09-18 17:40:42 +0000] [1] [INFO] Using worker: gevent
[2020-09-18 17:40:42 +0000] [7] [INFO] Booting worker with pid: 7
[2020-09-18 17:40:42 +0000] [8] [INFO] Booting worker with pid: 8
[2020-09-18 17:40:42 +0000] [9] [INFO] Booting worker with pid: 9
Traceback (most recent call last):
  File "/usr/local/lib/python3.8/dist-packages/gunicorn/arbiter.py", line 209, in run
    self.sleep()
  File "/usr/local/lib/python3.8/dist-packages/gunicorn/arbiter.py", line 357, in sleep
    ready = select.select([self.PIPE[0]], [], [], 1.0)
  File "/usr/local/lib/python3.8/dist-packages/gunicorn/arbiter.py", line 242, in handle_chld
    self.reap_workers()
  File "/usr/local/lib/python3.8/dist-packages/gunicorn/arbiter.py", line 525, in reap_workers
    raise HaltServer(reason, self.WORKER_BOOT_ERROR)
gunicorn.errors.HaltServer: <HaltServer 'Worker failed to boot.' 3>

During handling of the above exception, another exception occurred:

Traceback (most recent call last):
  File "/usr/local/bin/gunicorn", line 8, in <module>
    sys.exit(run())
  File "/usr/local/lib/python3.8/dist-packages/gunicorn/app/wsgiapp.py", line 58, in run
    WSGIApplication("%(prog)s [OPTIONS] [APP_MODULE]").run()
  File "/usr/local/lib/python3.8/dist-packages/gunicorn/app/base.py", line 228, in run
    super().run()
  File "/usr/local/lib/python3.8/dist-packages/gunicorn/app/base.py", line 72, in run
    Arbiter(self).run()
  File "/usr/local/lib/python3.8/dist-packages/gunicorn/arbiter.py", line 229, in run
    self.halt(reason=inst.reason, exit_status=inst.exit_status)
  File "/usr/local/lib/python3.8/dist-packages/gunicorn/arbiter.py", line 342, in halt
    self.stop()
  File "/usr/local/lib/python3.8/dist-packages/gunicorn/arbiter.py", line 393, in stop
    time.sleep(0.1)
  File "/usr/local/lib/python3.8/dist-packages/gunicorn/arbiter.py", line 242, in handle_chld
    self.reap_workers()
  File "/usr/local/lib/python3.8/dist-packages/gunicorn/arbiter.py", line 525, in reap_workers
    raise HaltServer(reason, self.WORKER_BOOT_ERROR)
gunicorn.errors.HaltServer: <HaltServer 'Worker failed to boot.' 3>
[2020-09-18 17:46:28 +0000] [1] [INFO] Starting gunicorn 20.0.4
[2020-09-18 17:46:28 +0000] [1] [INFO] Listening at: http://0.0.0.0:5000 (1)
[2020-09-18 17:46:28 +0000] [1] [INFO] Using worker: gevent
[2020-09-18 17:46:28 +0000] [9] [INFO] Booting worker with pid: 9
[2020-09-18 17:46:29 +0000] [10] [INFO] Booting worker with pid: 10
[2020-09-18 17:46:29 +0000] [11] [INFO] Booting worker with pid: 11
Traceback (most recent call last):
  File "/usr/local/lib/python3.8/dist-packages/gunicorn/arbiter.py", line 209, in run
    self.sleep()
  File "/usr/local/lib/python3.8/dist-packages/gunicorn/arbiter.py", line 357, in sleep
    ready = select.select([self.PIPE[0]], [], [], 1.0)
  File "/usr/local/lib/python3.8/dist-packages/gunicorn/arbiter.py", line 242, in handle_chld
    self.reap_workers()
  File "/usr/local/lib/python3.8/dist-packages/gunicorn/arbiter.py", line 525, in reap_workers
    raise HaltServer(reason, self.WORKER_BOOT_ERROR)
gunicorn.errors.HaltServer: <HaltServer 'Worker failed to boot.' 3>

During handling of the above exception, another exception occurred:

Traceback (most recent call last):
  File "/usr/local/bin/gunicorn", line 8, in <module>
    sys.exit(run())
  File "/usr/local/lib/python3.8/dist-packages/gunicorn/app/wsgiapp.py", line 58, in run
    WSGIApplication("%(prog)s [OPTIONS] [APP_MODULE]").run()
  File "/usr/local/lib/python3.8/dist-packages/gunicorn/app/base.py", line 228, in run
    super().run()
  File "/usr/local/lib/python3.8/dist-packages/gunicorn/app/base.py", line 72, in run
    Arbiter(self).run()
  File "/usr/local/lib/python3.8/dist-packages/gunicorn/arbiter.py", line 229, in run
    self.halt(reason=inst.reason, exit_status=inst.exit_status)
  File "/usr/local/lib/python3.8/dist-packages/gunicorn/arbiter.py", line 342, in halt
    self.stop()
  File "/usr/local/lib/python3.8/dist-packages/gunicorn/arbiter.py", line 393, in stop
    time.sleep(0.1)
  File "/usr/local/lib/python3.8/dist-packages/gunicorn/arbiter.py", line 242, in handle_chld
    self.reap_workers()
  File "/usr/local/lib/python3.8/dist-packages/gunicorn/arbiter.py", line 525, in reap_workers
    raise HaltServer(reason, self.WORKER_BOOT_ERROR)
gunicorn.errors.HaltServer: <HaltServer 'Worker failed to boot.' 3>
[2020-09-18 17:49:13 +0000] [1] [INFO] Starting gunicorn 20.0.4
[2020-09-18 17:49:13 +0000] [1] [INFO] Listening at: http://0.0.0.0:5000 (1)
[2020-09-18 17:49:13 +0000] [1] [INFO] Using worker: gevent
[2020-09-18 17:49:13 +0000] [7] [INFO] Booting worker with pid: 7
[2020-09-18 17:49:13 +0000] [8] [INFO] Booting worker with pid: 8
[2020-09-18 17:49:13 +0000] [9] [INFO] Booting worker with pid: 9
Traceback (most recent call last):
  File "/usr/local/lib/python3.8/dist-packages/gunicorn/arbiter.py", line 209, in run
    self.sleep()
  File "/usr/local/lib/python3.8/dist-packages/gunicorn/arbiter.py", line 357, in sleep
    ready = select.select([self.PIPE[0]], [], [], 1.0)
  File "/usr/local/lib/python3.8/dist-packages/gunicorn/arbiter.py", line 242, in handle_chld
    self.reap_workers()
  File "/usr/local/lib/python3.8/dist-packages/gunicorn/arbiter.py", line 525, in reap_workers
    raise HaltServer(reason, self.WORKER_BOOT_ERROR)
gunicorn.errors.HaltServer: <HaltServer 'Worker failed to boot.' 3>

During handling of the above exception, another exception occurred:

Traceback (most recent call last):
  File "/usr/local/bin/gunicorn", line 8, in <module>
    sys.exit(run())
  File "/usr/local/lib/python3.8/dist-packages/gunicorn/app/wsgiapp.py", line 58, in run
    WSGIApplication("%(prog)s [OPTIONS] [APP_MODULE]").run()
  File "/usr/local/lib/python3.8/dist-packages/gunicorn/app/base.py", line 228, in run
    super().run()
  File "/usr/local/lib/python3.8/dist-packages/gunicorn/app/base.py", line 72, in run
    Arbiter(self).run()
  File "/usr/local/lib/python3.8/dist-packages/gunicorn/arbiter.py", line 229, in run
    self.halt(reason=inst.reason, exit_status=inst.exit_status)
  File "/usr/local/lib/python3.8/dist-packages/gunicorn/arbiter.py", line 342, in halt
    self.stop()
  File "/usr/local/lib/python3.8/dist-packages/gunicorn/arbiter.py", line 393, in stop
    time.sleep(0.1)
  File "/usr/local/lib/python3.8/dist-packages/gunicorn/arbiter.py", line 242, in handle_chld
    self.reap_workers()
  File "/usr/local/lib/python3.8/dist-packages/gunicorn/arbiter.py", line 525, in reap_workers
    raise HaltServer(reason, self.WORKER_BOOT_ERROR)
gunicorn.errors.HaltServer: <HaltServer 'Worker failed to boot.' 3>
[2020-09-18 17:49:45 +0000] [1] [INFO] Starting gunicorn 20.0.4
[2020-09-18 17:49:45 +0000] [1] [INFO] Listening at: http://0.0.0.0:5000 (1)
[2020-09-18 17:49:45 +0000] [1] [INFO] Using worker: gevent
[2020-09-18 17:49:45 +0000] [8] [INFO] Booting worker with pid: 8
[2020-09-18 17:49:45 +0000] [9] [INFO] Booting worker with pid: 9
[2020-09-18 17:49:45 +0000] [10] [INFO] Booting worker with pid: 10
Traceback (most recent call last):
  File "/usr/local/lib/python3.8/dist-packages/gunicorn/arbiter.py", line 209, in run
    self.sleep()
  File "/usr/local/lib/python3.8/dist-packages/gunicorn/arbiter.py", line 357, in sleep
    ready = select.select([self.PIPE[0]], [], [], 1.0)
  File "/usr/local/lib/python3.8/dist-packages/gunicorn/arbiter.py", line 242, in handle_chld
    self.reap_workers()
  File "/usr/local/lib/python3.8/dist-packages/gunicorn/arbiter.py", line 525, in reap_workers
    raise HaltServer(reason, self.WORKER_BOOT_ERROR)
gunicorn.errors.HaltServer: <HaltServer 'Worker failed to boot.' 3>

During handling of the above exception, another exception occurred:

Traceback (most recent call last):
  File "/usr/local/bin/gunicorn", line 8, in <module>
    sys.exit(run())
  File "/usr/local/lib/python3.8/dist-packages/gunicorn/app/wsgiapp.py", line 58, in run
    WSGIApplication("%(prog)s [OPTIONS] [APP_MODULE]").run()
  File "/usr/local/lib/python3.8/dist-packages/gunicorn/app/base.py", line 228, in run
    super().run()
  File "/usr/local/lib/python3.8/dist-packages/gunicorn/app/base.py", line 72, in run
    Arbiter(self).run()
  File "/usr/local/lib/python3.8/dist-packages/gunicorn/arbiter.py", line 229, in run
    self.halt(reason=inst.reason, exit_status=inst.exit_status)
  File "/usr/local/lib/python3.8/dist-packages/gunicorn/arbiter.py", line 342, in halt
    self.stop()
  File "/usr/local/lib/python3.8/dist-packages/gunicorn/arbiter.py", line 393, in stop
    time.sleep(0.1)
  File "/usr/local/lib/python3.8/dist-packages/gunicorn/arbiter.py", line 242, in handle_chld
    self.reap_workers()
  File "/usr/local/lib/python3.8/dist-packages/gunicorn/arbiter.py", line 525, in reap_workers
    raise HaltServer(reason, self.WORKER_BOOT_ERROR)
gunicorn.errors.HaltServer: <HaltServer 'Worker failed to boot.' 3>
[2020-09-18 17:51:33 +0000] [1] [INFO] Starting gunicorn 20.0.4
[2020-09-18 17:51:33 +0000] [1] [INFO] Listening at: http://0.0.0.0:5000 (1)
[2020-09-18 17:51:33 +0000] [1] [INFO] Using worker: gevent
[2020-09-18 17:51:33 +0000] [7] [INFO] Booting worker with pid: 7
[2020-09-18 17:51:34 +0000] [8] [INFO] Booting worker with pid: 8
[2020-09-18 17:51:34 +0000] [9] [INFO] Booting worker with pid: 9
[2020-09-18 17:52:14 +0000] [1] [INFO] Handling signal: term
[2020-09-18 17:52:15 +0000] [1] [INFO] Shutting down: Master
[2020-09-18 17:52:27 +0000] [1] [INFO] Starting gunicorn 20.0.4
[2020-09-18 17:52:27 +0000] [1] [INFO] Listening at: http://0.0.0.0:5000 (1)
[2020-09-18 17:52:27 +0000] [1] [INFO] Using worker: gevent
[2020-09-18 17:52:27 +0000] [10] [INFO] Booting worker with pid: 10
[2020-09-18 17:52:27 +0000] [11] [INFO] Booting worker with pid: 11
[2020-09-18 17:52:27 +0000] [12] [INFO] Booting worker with pid: 12
Traceback (most recent call last):
  File "/usr/local/lib/python3.8/dist-packages/gunicorn/arbiter.py", line 209, in run
    self.sleep()
  File "/usr/local/lib/python3.8/dist-packages/gunicorn/arbiter.py", line 357, in sleep
    ready = select.select([self.PIPE[0]], [], [], 1.0)
  File "/usr/local/lib/python3.8/dist-packages/gunicorn/arbiter.py", line 242, in handle_chld
    self.reap_workers()
  File "/usr/local/lib/python3.8/dist-packages/gunicorn/arbiter.py", line 525, in reap_workers
    raise HaltServer(reason, self.WORKER_BOOT_ERROR)
gunicorn.errors.HaltServer: <HaltServer 'Worker failed to boot.' 3>

During handling of the above exception, another exception occurred:

Traceback (most recent call last):
  File "/usr/local/bin/gunicorn", line 8, in <module>
    sys.exit(run())
  File "/usr/local/lib/python3.8/dist-packages/gunicorn/app/wsgiapp.py", line 58, in run
    WSGIApplication("%(prog)s [OPTIONS] [APP_MODULE]").run()
  File "/usr/local/lib/python3.8/dist-packages/gunicorn/app/base.py", line 228, in run
    super().run()
  File "/usr/local/lib/python3.8/dist-packages/gunicorn/app/base.py", line 72, in run
    Arbiter(self).run()
  File "/usr/local/lib/python3.8/dist-packages/gunicorn/arbiter.py", line 229, in run
    self.halt(reason=inst.reason, exit_status=inst.exit_status)
  File "/usr/local/lib/python3.8/dist-packages/gunicorn/arbiter.py", line 342, in halt
    self.stop()
  File "/usr/local/lib/python3.8/dist-packages/gunicorn/arbiter.py", line 393, in stop
    time.sleep(0.1)
  File "/usr/local/lib/python3.8/dist-packages/gunicorn/arbiter.py", line 242, in handle_chld
    self.reap_workers()
  File "/usr/local/lib/python3.8/dist-packages/gunicorn/arbiter.py", line 525, in reap_workers
    raise HaltServer(reason, self.WORKER_BOOT_ERROR)
gunicorn.errors.HaltServer: <HaltServer 'Worker failed to boot.' 3>
[2020-09-18 17:52:32 +0000] [1] [INFO] Starting gunicorn 20.0.4
[2020-09-18 17:52:32 +0000] [1] [INFO] Listening at: http://0.0.0.0:5000 (1)
[2020-09-18 17:52:32 +0000] [1] [INFO] Using worker: gevent
[2020-09-18 17:52:32 +0000] [7] [INFO] Booting worker with pid: 7
[2020-09-18 17:52:32 +0000] [8] [INFO] Booting worker with pid: 8
[2020-09-18 17:52:32 +0000] [9] [INFO] Booting worker with pid: 9
Traceback (most recent call last):
  File "/usr/local/lib/python3.8/dist-packages/gunicorn/arbiter.py", line 209, in run
    self.sleep()
  File "/usr/local/lib/python3.8/dist-packages/gunicorn/arbiter.py", line 357, in sleep
    ready = select.select([self.PIPE[0]], [], [], 1.0)
  File "/usr/local/lib/python3.8/dist-packages/gunicorn/arbiter.py", line 242, in handle_chld
    self.reap_workers()
  File "/usr/local/lib/python3.8/dist-packages/gunicorn/arbiter.py", line 525, in reap_workers
    raise HaltServer(reason, self.WORKER_BOOT_ERROR)
gunicorn.errors.HaltServer: <HaltServer 'Worker failed to boot.' 3>

During handling of the above exception, another exception occurred:

Traceback (most recent call last):
  File "/usr/local/bin/gunicorn", line 8, in <module>
    sys.exit(run())
  File "/usr/local/lib/python3.8/dist-packages/gunicorn/app/wsgiapp.py", line 58, in run
    WSGIApplication("%(prog)s [OPTIONS] [APP_MODULE]").run()
  File "/usr/local/lib/python3.8/dist-packages/gunicorn/app/base.py", line 228, in run
    super().run()
  File "/usr/local/lib/python3.8/dist-packages/gunicorn/app/base.py", line 72, in run
    Arbiter(self).run()
  File "/usr/local/lib/python3.8/dist-packages/gunicorn/arbiter.py", line 229, in run
    self.halt(reason=inst.reason, exit_status=inst.exit_status)
  File "/usr/local/lib/python3.8/dist-packages/gunicorn/arbiter.py", line 342, in halt
    self.stop()
  File "/usr/local/lib/python3.8/dist-packages/gunicorn/arbiter.py", line 393, in stop
    time.sleep(0.1)
  File "/usr/local/lib/python3.8/dist-packages/gunicorn/arbiter.py", line 242, in handle_chld
    self.reap_workers()
  File "/usr/local/lib/python3.8/dist-packages/gunicorn/arbiter.py", line 525, in reap_workers
    raise HaltServer(reason, self.WORKER_BOOT_ERROR)
gunicorn.errors.HaltServer: <HaltServer 'Worker failed to boot.' 3>
[2020-09-18 17:52:53 +0000] [1] [INFO] Starting gunicorn 20.0.4
[2020-09-18 17:52:53 +0000] [1] [INFO] Listening at: http://0.0.0.0:5000 (1)
[2020-09-18 17:52:53 +0000] [1] [INFO] Using worker: gevent
[2020-09-18 17:52:53 +0000] [7] [INFO] Booting worker with pid: 7
[2020-09-18 17:52:53 +0000] [8] [INFO] Booting worker with pid: 8
[2020-09-18 17:52:53 +0000] [9] [INFO] Booting worker with pid: 9
[2020-09-18 17:52:54 +0000] [1] [INFO] Shutting down: Master
[2020-09-18 17:52:54 +0000] [1] [INFO] Reason: Worker failed to boot.
[2020-09-18 18:00:49 +0000] [1] [INFO] Starting gunicorn 20.0.4
[2020-09-18 18:00:49 +0000] [1] [INFO] Listening at: http://0.0.0.0:5000 (1)
[2020-09-18 18:00:49 +0000] [1] [INFO] Using worker: gevent
[2020-09-18 18:00:49 +0000] [7] [INFO] Booting worker with pid: 7
[2020-09-18 18:00:49 +0000] [8] [INFO] Booting worker with pid: 8
[2020-09-18 18:00:49 +0000] [9] [INFO] Booting worker with pid: 9
Traceback (most recent call last):
  File "/usr/local/lib/python3.8/dist-packages/gunicorn/arbiter.py", line 209, in run
    self.sleep()
  File "/usr/local/lib/python3.8/dist-packages/gunicorn/arbiter.py", line 357, in sleep
    ready = select.select([self.PIPE[0]], [], [], 1.0)
  File "/usr/local/lib/python3.8/dist-packages/gunicorn/arbiter.py", line 242, in handle_chld
    self.reap_workers()
  File "/usr/local/lib/python3.8/dist-packages/gunicorn/arbiter.py", line 525, in reap_workers
    raise HaltServer(reason, self.WORKER_BOOT_ERROR)
gunicorn.errors.HaltServer: <HaltServer 'Worker failed to boot.' 3>

During handling of the above exception, another exception occurred:

Traceback (most recent call last):
  File "/usr/local/bin/gunicorn", line 8, in <module>
    sys.exit(run())
  File "/usr/local/lib/python3.8/dist-packages/gunicorn/app/wsgiapp.py", line 58, in run
    WSGIApplication("%(prog)s [OPTIONS] [APP_MODULE]").run()
  File "/usr/local/lib/python3.8/dist-packages/gunicorn/app/base.py", line 228, in run
    super().run()
  File "/usr/local/lib/python3.8/dist-packages/gunicorn/app/base.py", line 72, in run
    Arbiter(self).run()
  File "/usr/local/lib/python3.8/dist-packages/gunicorn/arbiter.py", line 229, in run
    self.halt(reason=inst.reason, exit_status=inst.exit_status)
  File "/usr/local/lib/python3.8/dist-packages/gunicorn/arbiter.py", line 342, in halt
    self.stop()
  File "/usr/local/lib/python3.8/dist-packages/gunicorn/arbiter.py", line 393, in stop
    time.sleep(0.1)
  File "/usr/local/lib/python3.8/dist-packages/gunicorn/arbiter.py", line 242, in handle_chld
    self.reap_workers()
  File "/usr/local/lib/python3.8/dist-packages/gunicorn/arbiter.py", line 525, in reap_workers
    raise HaltServer(reason, self.WORKER_BOOT_ERROR)
gunicorn.errors.HaltServer: <HaltServer 'Worker failed to boot.' 3>
[2020-09-18 18:03:23 +0000] [1] [INFO] Starting gunicorn 20.0.4
[2020-09-18 18:03:23 +0000] [1] [INFO] Listening at: http://0.0.0.0:5000 (1)
[2020-09-18 18:03:23 +0000] [1] [INFO] Using worker: gevent
[2020-09-18 18:03:23 +0000] [7] [INFO] Booting worker with pid: 7
[2020-09-18 18:03:23 +0000] [8] [INFO] Booting worker with pid: 8
[2020-09-18 18:03:23 +0000] [9] [INFO] Booting worker with pid: 9
[2020-09-18 18:03:25 +0000] [1] [INFO] Shutting down: Master
[2020-09-18 18:03:25 +0000] [1] [INFO] Reason: Worker failed to boot.
[2020-09-18 18:03:50 +0000] [1] [INFO] Starting gunicorn 20.0.4
[2020-09-18 18:03:50 +0000] [1] [INFO] Listening at: http://0.0.0.0:5000 (1)
[2020-09-18 18:03:50 +0000] [1] [INFO] Using worker: gevent
[2020-09-18 18:03:50 +0000] [8] [INFO] Booting worker with pid: 8
[2020-09-18 18:03:50 +0000] [9] [INFO] Booting worker with pid: 9
[2020-09-18 18:03:50 +0000] [10] [INFO] Booting worker with pid: 10
Traceback (most recent call last):
  File "/usr/local/lib/python3.8/dist-packages/gunicorn/arbiter.py", line 209, in run
    self.sleep()
  File "/usr/local/lib/python3.8/dist-packages/gunicorn/arbiter.py", line 357, in sleep
    ready = select.select([self.PIPE[0]], [], [], 1.0)
  File "/usr/local/lib/python3.8/dist-packages/gunicorn/arbiter.py", line 242, in handle_chld
    self.reap_workers()
  File "/usr/local/lib/python3.8/dist-packages/gunicorn/arbiter.py", line 525, in reap_workers
    raise HaltServer(reason, self.WORKER_BOOT_ERROR)
gunicorn.errors.HaltServer: <HaltServer 'Worker failed to boot.' 3>

During handling of the above exception, another exception occurred:

Traceback (most recent call last):
  File "/usr/local/bin/gunicorn", line 8, in <module>
    sys.exit(run())
  File "/usr/local/lib/python3.8/dist-packages/gunicorn/app/wsgiapp.py", line 58, in run
    WSGIApplication("%(prog)s [OPTIONS] [APP_MODULE]").run()
  File "/usr/local/lib/python3.8/dist-packages/gunicorn/app/base.py", line 228, in run
    super().run()
  File "/usr/local/lib/python3.8/dist-packages/gunicorn/app/base.py", line 72, in run
    Arbiter(self).run()
  File "/usr/local/lib/python3.8/dist-packages/gunicorn/arbiter.py", line 229, in run
    self.halt(reason=inst.reason, exit_status=inst.exit_status)
  File "/usr/local/lib/python3.8/dist-packages/gunicorn/arbiter.py", line 342, in halt
    self.stop()
  File "/usr/local/lib/python3.8/dist-packages/gunicorn/arbiter.py", line 393, in stop
    time.sleep(0.1)
  File "/usr/local/lib/python3.8/dist-packages/gunicorn/arbiter.py", line 242, in handle_chld
    self.reap_workers()
  File "/usr/local/lib/python3.8/dist-packages/gunicorn/arbiter.py", line 525, in reap_workers
    raise HaltServer(reason, self.WORKER_BOOT_ERROR)
gunicorn.errors.HaltServer: <HaltServer 'Worker failed to boot.' 3>
[2020-09-18 18:04:16 +0000] [1] [INFO] Starting gunicorn 20.0.4
[2020-09-18 18:04:16 +0000] [1] [INFO] Listening at: http://0.0.0.0:5000 (1)
[2020-09-18 18:04:16 +0000] [1] [INFO] Using worker: gevent
[2020-09-18 18:04:16 +0000] [7] [INFO] Booting worker with pid: 7
[2020-09-18 18:04:16 +0000] [8] [INFO] Booting worker with pid: 8
[2020-09-18 18:04:16 +0000] [9] [INFO] Booting worker with pid: 9
Traceback (most recent call last):
  File "/usr/local/lib/python3.8/dist-packages/gunicorn/arbiter.py", line 209, in run
    self.sleep()
  File "/usr/local/lib/python3.8/dist-packages/gunicorn/arbiter.py", line 357, in sleep
    ready = select.select([self.PIPE[0]], [], [], 1.0)
  File "/usr/local/lib/python3.8/dist-packages/gunicorn/arbiter.py", line 242, in handle_chld
    self.reap_workers()
  File "/usr/local/lib/python3.8/dist-packages/gunicorn/arbiter.py", line 525, in reap_workers
    raise HaltServer(reason, self.WORKER_BOOT_ERROR)
gunicorn.errors.HaltServer: <HaltServer 'Worker failed to boot.' 3>

During handling of the above exception, another exception occurred:

Traceback (most recent call last):
  File "/usr/local/bin/gunicorn", line 8, in <module>
    sys.exit(run())
  File "/usr/local/lib/python3.8/dist-packages/gunicorn/app/wsgiapp.py", line 58, in run
    WSGIApplication("%(prog)s [OPTIONS] [APP_MODULE]").run()
  File "/usr/local/lib/python3.8/dist-packages/gunicorn/app/base.py", line 228, in run
    super().run()
  File "/usr/local/lib/python3.8/dist-packages/gunicorn/app/base.py", line 72, in run
    Arbiter(self).run()
  File "/usr/local/lib/python3.8/dist-packages/gunicorn/arbiter.py", line 229, in run
    self.halt(reason=inst.reason, exit_status=inst.exit_status)
  File "/usr/local/lib/python3.8/dist-packages/gunicorn/arbiter.py", line 342, in halt
    self.stop()
  File "/usr/local/lib/python3.8/dist-packages/gunicorn/arbiter.py", line 393, in stop
    time.sleep(0.1)
  File "/usr/local/lib/python3.8/dist-packages/gunicorn/arbiter.py", line 242, in handle_chld
    self.reap_workers()
  File "/usr/local/lib/python3.8/dist-packages/gunicorn/arbiter.py", line 525, in reap_workers
    raise HaltServer(reason, self.WORKER_BOOT_ERROR)
gunicorn.errors.HaltServer: <HaltServer 'Worker failed to boot.' 3>
[2020-09-18 18:04:27 +0000] [1] [INFO] Starting gunicorn 20.0.4
[2020-09-18 18:04:27 +0000] [1] [INFO] Listening at: http://0.0.0.0:5000 (1)
[2020-09-18 18:04:27 +0000] [1] [INFO] Using worker: gevent
[2020-09-18 18:04:27 +0000] [7] [INFO] Booting worker with pid: 7
[2020-09-18 18:04:27 +0000] [8] [INFO] Booting worker with pid: 8
[2020-09-18 18:04:27 +0000] [9] [INFO] Booting worker with pid: 9
Traceback (most recent call last):
  File "/usr/local/lib/python3.8/dist-packages/gunicorn/arbiter.py", line 209, in run
    self.sleep()
  File "/usr/local/lib/python3.8/dist-packages/gunicorn/arbiter.py", line 357, in sleep
    ready = select.select([self.PIPE[0]], [], [], 1.0)
  File "/usr/local/lib/python3.8/dist-packages/gunicorn/arbiter.py", line 242, in handle_chld
    self.reap_workers()
  File "/usr/local/lib/python3.8/dist-packages/gunicorn/arbiter.py", line 525, in reap_workers
    raise HaltServer(reason, self.WORKER_BOOT_ERROR)
gunicorn.errors.HaltServer: <HaltServer 'Worker failed to boot.' 3>

During handling of the above exception, another exception occurred:

Traceback (most recent call last):
  File "/usr/local/bin/gunicorn", line 8, in <module>
    sys.exit(run())
  File "/usr/local/lib/python3.8/dist-packages/gunicorn/app/wsgiapp.py", line 58, in run
    WSGIApplication("%(prog)s [OPTIONS] [APP_MODULE]").run()
  File "/usr/local/lib/python3.8/dist-packages/gunicorn/app/base.py", line 228, in run
    super().run()
  File "/usr/local/lib/python3.8/dist-packages/gunicorn/app/base.py", line 72, in run
    Arbiter(self).run()
  File "/usr/local/lib/python3.8/dist-packages/gunicorn/arbiter.py", line 229, in run
    self.halt(reason=inst.reason, exit_status=inst.exit_status)
  File "/usr/local/lib/python3.8/dist-packages/gunicorn/arbiter.py", line 342, in halt
    self.stop()
  File "/usr/local/lib/python3.8/dist-packages/gunicorn/arbiter.py", line 393, in stop
    time.sleep(0.1)
  File "/usr/local/lib/python3.8/dist-packages/gunicorn/arbiter.py", line 242, in handle_chld
    self.reap_workers()
  File "/usr/local/lib/python3.8/dist-packages/gunicorn/arbiter.py", line 525, in reap_workers
    raise HaltServer(reason, self.WORKER_BOOT_ERROR)
gunicorn.errors.HaltServer: <HaltServer 'Worker failed to boot.' 3>
[2020-09-18 18:05:50 +0000] [1] [INFO] Starting gunicorn 20.0.4
[2020-09-18 18:05:50 +0000] [1] [INFO] Listening at: http://0.0.0.0:5000 (1)
[2020-09-18 18:05:50 +0000] [1] [INFO] Using worker: gevent
[2020-09-18 18:05:50 +0000] [7] [INFO] Booting worker with pid: 7
[2020-09-18 18:05:50 +0000] [8] [INFO] Booting worker with pid: 8
[2020-09-18 18:05:50 +0000] [9] [INFO] Booting worker with pid: 9
[2020-09-18 18:10:11 +0000] [1] [INFO] Handling signal: term
[2020-09-18 18:10:12 +0000] [1] [INFO] Shutting down: Master
[2020-09-18 18:10:19 +0000] [1] [INFO] Starting gunicorn 20.0.4
[2020-09-18 18:10:19 +0000] [1] [INFO] Listening at: http://0.0.0.0:5000 (1)
[2020-09-18 18:10:19 +0000] [1] [INFO] Using worker: gevent
[2020-09-18 18:10:19 +0000] [7] [INFO] Booting worker with pid: 7
[2020-09-18 18:10:19 +0000] [8] [INFO] Booting worker with pid: 8
[2020-09-18 18:10:19 +0000] [9] [INFO] Booting worker with pid: 9
[2020-09-18 18:10:21 +0000] [1] [INFO] Shutting down: Master
[2020-09-18 18:10:21 +0000] [1] [INFO] Reason: Worker failed to boot.
[2020-09-18 18:11:44 +0000] [1] [INFO] Starting gunicorn 20.0.4
[2020-09-18 18:11:44 +0000] [1] [INFO] Listening at: http://0.0.0.0:5000 (1)
[2020-09-18 18:11:44 +0000] [1] [INFO] Using worker: gevent
[2020-09-18 18:11:44 +0000] [7] [INFO] Booting worker with pid: 7
[2020-09-18 18:11:44 +0000] [8] [INFO] Booting worker with pid: 8
[2020-09-18 18:11:44 +0000] [9] [INFO] Booting worker with pid: 9
Traceback (most recent call last):
  File "/usr/local/lib/python3.8/dist-packages/gunicorn/arbiter.py", line 209, in run
    self.sleep()
  File "/usr/local/lib/python3.8/dist-packages/gunicorn/arbiter.py", line 357, in sleep
    ready = select.select([self.PIPE[0]], [], [], 1.0)
  File "/usr/local/lib/python3.8/dist-packages/gunicorn/arbiter.py", line 242, in handle_chld
    self.reap_workers()
  File "/usr/local/lib/python3.8/dist-packages/gunicorn/arbiter.py", line 513, in reap_workers
    wpid, status = os.waitpid(-1, os.WNOHANG)
  File "/usr/local/lib/python3.8/dist-packages/gunicorn/arbiter.py", line 242, in handle_chld
    self.reap_workers()
  File "/usr/local/lib/python3.8/dist-packages/gunicorn/arbiter.py", line 525, in reap_workers
    raise HaltServer(reason, self.WORKER_BOOT_ERROR)
gunicorn.errors.HaltServer: <HaltServer 'Worker failed to boot.' 3>

During handling of the above exception, another exception occurred:

Traceback (most recent call last):
  File "/usr/local/bin/gunicorn", line 8, in <module>
    sys.exit(run())
  File "/usr/local/lib/python3.8/dist-packages/gunicorn/app/wsgiapp.py", line 58, in run
    WSGIApplication("%(prog)s [OPTIONS] [APP_MODULE]").run()
  File "/usr/local/lib/python3.8/dist-packages/gunicorn/app/base.py", line 228, in run
    super().run()
  File "/usr/local/lib/python3.8/dist-packages/gunicorn/app/base.py", line 72, in run
    Arbiter(self).run()
  File "/usr/local/lib/python3.8/dist-packages/gunicorn/arbiter.py", line 229, in run
    self.halt(reason=inst.reason, exit_status=inst.exit_status)
  File "/usr/local/lib/python3.8/dist-packages/gunicorn/arbiter.py", line 342, in halt
    self.stop()
  File "/usr/local/lib/python3.8/dist-packages/gunicorn/arbiter.py", line 393, in stop
    time.sleep(0.1)
  File "/usr/local/lib/python3.8/dist-packages/gunicorn/arbiter.py", line 242, in handle_chld
    self.reap_workers()
  File "/usr/local/lib/python3.8/dist-packages/gunicorn/arbiter.py", line 525, in reap_workers
    raise HaltServer(reason, self.WORKER_BOOT_ERROR)
gunicorn.errors.HaltServer: <HaltServer 'Worker failed to boot.' 3>
[2020-09-18 18:12:07 +0000] [1] [INFO] Starting gunicorn 20.0.4
[2020-09-18 18:12:07 +0000] [1] [INFO] Listening at: http://0.0.0.0:5000 (1)
[2020-09-18 18:12:07 +0000] [1] [INFO] Using worker: gevent
[2020-09-18 18:12:07 +0000] [7] [INFO] Booting worker with pid: 7
[2020-09-18 18:12:07 +0000] [8] [INFO] Booting worker with pid: 8
[2020-09-18 18:12:07 +0000] [9] [INFO] Booting worker with pid: 9
Traceback (most recent call last):
  File "/usr/local/lib/python3.8/dist-packages/gunicorn/arbiter.py", line 209, in run
    self.sleep()
  File "/usr/local/lib/python3.8/dist-packages/gunicorn/arbiter.py", line 357, in sleep
    ready = select.select([self.PIPE[0]], [], [], 1.0)
  File "/usr/local/lib/python3.8/dist-packages/gunicorn/arbiter.py", line 242, in handle_chld
    self.reap_workers()
  File "/usr/local/lib/python3.8/dist-packages/gunicorn/arbiter.py", line 525, in reap_workers
    raise HaltServer(reason, self.WORKER_BOOT_ERROR)
gunicorn.errors.HaltServer: <HaltServer 'Worker failed to boot.' 3>

During handling of the above exception, another exception occurred:

Traceback (most recent call last):
  File "/usr/local/bin/gunicorn", line 8, in <module>
    sys.exit(run())
  File "/usr/local/lib/python3.8/dist-packages/gunicorn/app/wsgiapp.py", line 58, in run
    WSGIApplication("%(prog)s [OPTIONS] [APP_MODULE]").run()
  File "/usr/local/lib/python3.8/dist-packages/gunicorn/app/base.py", line 228, in run
    super().run()
  File "/usr/local/lib/python3.8/dist-packages/gunicorn/app/base.py", line 72, in run
    Arbiter(self).run()
  File "/usr/local/lib/python3.8/dist-packages/gunicorn/arbiter.py", line 229, in run
    self.halt(reason=inst.reason, exit_status=inst.exit_status)
  File "/usr/local/lib/python3.8/dist-packages/gunicorn/arbiter.py", line 342, in halt
    self.stop()
  File "/usr/local/lib/python3.8/dist-packages/gunicorn/arbiter.py", line 393, in stop
    time.sleep(0.1)
  File "/usr/local/lib/python3.8/dist-packages/gunicorn/arbiter.py", line 242, in handle_chld
    self.reap_workers()
  File "/usr/local/lib/python3.8/dist-packages/gunicorn/arbiter.py", line 525, in reap_workers
    raise HaltServer(reason, self.WORKER_BOOT_ERROR)
gunicorn.errors.HaltServer: <HaltServer 'Worker failed to boot.' 3>
[2020-09-18 18:13:53 +0000] [1] [INFO] Starting gunicorn 20.0.4
[2020-09-18 18:13:53 +0000] [1] [INFO] Listening at: http://0.0.0.0:5000 (1)
[2020-09-18 18:13:53 +0000] [1] [INFO] Using worker: gevent
[2020-09-18 18:13:53 +0000] [7] [INFO] Booting worker with pid: 7
[2020-09-18 18:13:53 +0000] [8] [INFO] Booting worker with pid: 8
[2020-09-18 18:13:53 +0000] [9] [INFO] Booting worker with pid: 9
Traceback (most recent call last):
  File "/usr/local/lib/python3.8/dist-packages/gunicorn/arbiter.py", line 209, in run
    self.sleep()
  File "/usr/local/lib/python3.8/dist-packages/gunicorn/arbiter.py", line 357, in sleep
    ready = select.select([self.PIPE[0]], [], [], 1.0)
  File "/usr/local/lib/python3.8/dist-packages/gunicorn/arbiter.py", line 242, in handle_chld
    self.reap_workers()
  File "/usr/local/lib/python3.8/dist-packages/gunicorn/arbiter.py", line 525, in reap_workers
    raise HaltServer(reason, self.WORKER_BOOT_ERROR)
gunicorn.errors.HaltServer: <HaltServer 'Worker failed to boot.' 3>

During handling of the above exception, another exception occurred:

Traceback (most recent call last):
  File "/usr/local/bin/gunicorn", line 8, in <module>
    sys.exit(run())
  File "/usr/local/lib/python3.8/dist-packages/gunicorn/app/wsgiapp.py", line 58, in run
    WSGIApplication("%(prog)s [OPTIONS] [APP_MODULE]").run()
  File "/usr/local/lib/python3.8/dist-packages/gunicorn/app/base.py", line 228, in run
    super().run()
  File "/usr/local/lib/python3.8/dist-packages/gunicorn/app/base.py", line 72, in run
    Arbiter(self).run()
  File "/usr/local/lib/python3.8/dist-packages/gunicorn/arbiter.py", line 229, in run
    self.halt(reason=inst.reason, exit_status=inst.exit_status)
  File "/usr/local/lib/python3.8/dist-packages/gunicorn/arbiter.py", line 342, in halt
    self.stop()
  File "/usr/local/lib/python3.8/dist-packages/gunicorn/arbiter.py", line 393, in stop
    time.sleep(0.1)
  File "/usr/local/lib/python3.8/dist-packages/gunicorn/arbiter.py", line 242, in handle_chld
    self.reap_workers()
  File "/usr/local/lib/python3.8/dist-packages/gunicorn/arbiter.py", line 525, in reap_workers
    raise HaltServer(reason, self.WORKER_BOOT_ERROR)
gunicorn.errors.HaltServer: <HaltServer 'Worker failed to boot.' 3>
[2020-09-18 18:14:45 +0000] [1] [INFO] Starting gunicorn 20.0.4
[2020-09-18 18:14:45 +0000] [1] [INFO] Listening at: http://0.0.0.0:5000 (1)
[2020-09-18 18:14:45 +0000] [1] [INFO] Using worker: gevent
[2020-09-18 18:14:45 +0000] [7] [INFO] Booting worker with pid: 7
[2020-09-18 18:14:45 +0000] [8] [INFO] Booting worker with pid: 8
[2020-09-18 18:14:45 +0000] [9] [INFO] Booting worker with pid: 9
Traceback (most recent call last):
  File "/usr/local/lib/python3.8/dist-packages/gunicorn/arbiter.py", line 209, in run
    self.sleep()
  File "/usr/local/lib/python3.8/dist-packages/gunicorn/arbiter.py", line 357, in sleep
    ready = select.select([self.PIPE[0]], [], [], 1.0)
  File "/usr/local/lib/python3.8/dist-packages/gunicorn/arbiter.py", line 242, in handle_chld
    self.reap_workers()
  File "/usr/local/lib/python3.8/dist-packages/gunicorn/arbiter.py", line 525, in reap_workers
    raise HaltServer(reason, self.WORKER_BOOT_ERROR)
gunicorn.errors.HaltServer: <HaltServer 'Worker failed to boot.' 3>

During handling of the above exception, another exception occurred:

Traceback (most recent call last):
  File "/usr/local/bin/gunicorn", line 8, in <module>
    sys.exit(run())
  File "/usr/local/lib/python3.8/dist-packages/gunicorn/app/wsgiapp.py", line 58, in run
    WSGIApplication("%(prog)s [OPTIONS] [APP_MODULE]").run()
  File "/usr/local/lib/python3.8/dist-packages/gunicorn/app/base.py", line 228, in run
    super().run()
  File "/usr/local/lib/python3.8/dist-packages/gunicorn/app/base.py", line 72, in run
    Arbiter(self).run()
  File "/usr/local/lib/python3.8/dist-packages/gunicorn/arbiter.py", line 229, in run
    self.halt(reason=inst.reason, exit_status=inst.exit_status)
  File "/usr/local/lib/python3.8/dist-packages/gunicorn/arbiter.py", line 342, in halt
    self.stop()
  File "/usr/local/lib/python3.8/dist-packages/gunicorn/arbiter.py", line 393, in stop
    time.sleep(0.1)
  File "/usr/local/lib/python3.8/dist-packages/gunicorn/arbiter.py", line 242, in handle_chld
    self.reap_workers()
  File "/usr/local/lib/python3.8/dist-packages/gunicorn/arbiter.py", line 525, in reap_workers
    raise HaltServer(reason, self.WORKER_BOOT_ERROR)
gunicorn.errors.HaltServer: <HaltServer 'Worker failed to boot.' 3>
[2020-09-18 18:15:16 +0000] [1] [INFO] Starting gunicorn 20.0.4
[2020-09-18 18:15:16 +0000] [1] [INFO] Listening at: http://0.0.0.0:5000 (1)
[2020-09-18 18:15:16 +0000] [1] [INFO] Using worker: gevent
[2020-09-18 18:15:16 +0000] [8] [INFO] Booting worker with pid: 8
[2020-09-18 18:15:16 +0000] [9] [INFO] Booting worker with pid: 9
[2020-09-18 18:15:16 +0000] [10] [INFO] Booting worker with pid: 10
[2020-09-18 18:16:16 +0000] [1] [INFO] Handling signal: term
[2020-09-18 18:16:17 +0000] [1] [INFO] Shutting down: Master
[2020-09-18 18:16:24 +0000] [1] [INFO] Starting gunicorn 20.0.4
[2020-09-18 18:16:24 +0000] [1] [INFO] Listening at: http://0.0.0.0:5000 (1)
[2020-09-18 18:16:24 +0000] [1] [INFO] Using worker: gevent
[2020-09-18 18:16:24 +0000] [7] [INFO] Booting worker with pid: 7
[2020-09-18 18:16:24 +0000] [8] [INFO] Booting worker with pid: 8
[2020-09-18 18:16:24 +0000] [9] [INFO] Booting worker with pid: 9
[2020-09-18 18:17:43 +0000] [1] [INFO] Handling signal: term
[2020-09-18 18:17:44 +0000] [1] [INFO] Shutting down: Master
[2020-09-18 18:17:54 +0000] [1] [INFO] Starting gunicorn 20.0.4
[2020-09-18 18:17:54 +0000] [1] [INFO] Listening at: http://0.0.0.0:5000 (1)
[2020-09-18 18:17:54 +0000] [1] [INFO] Using worker: gevent
[2020-09-18 18:17:54 +0000] [8] [INFO] Booting worker with pid: 8
[2020-09-18 18:17:54 +0000] [9] [INFO] Booting worker with pid: 9
[2020-09-18 18:17:54 +0000] [10] [INFO] Booting worker with pid: 10
Traceback (most recent call last):
  File "/usr/local/lib/python3.8/dist-packages/gunicorn/arbiter.py", line 209, in run
    self.sleep()
  File "/usr/local/lib/python3.8/dist-packages/gunicorn/arbiter.py", line 357, in sleep
    ready = select.select([self.PIPE[0]], [], [], 1.0)
  File "/usr/local/lib/python3.8/dist-packages/gunicorn/arbiter.py", line 242, in handle_chld
    self.reap_workers()
  File "/usr/local/lib/python3.8/dist-packages/gunicorn/arbiter.py", line 525, in reap_workers
    raise HaltServer(reason, self.WORKER_BOOT_ERROR)
gunicorn.errors.HaltServer: <HaltServer 'Worker failed to boot.' 3>

During handling of the above exception, another exception occurred:

Traceback (most recent call last):
  File "/usr/local/bin/gunicorn", line 8, in <module>
    sys.exit(run())
  File "/usr/local/lib/python3.8/dist-packages/gunicorn/app/wsgiapp.py", line 58, in run
    WSGIApplication("%(prog)s [OPTIONS] [APP_MODULE]").run()
  File "/usr/local/lib/python3.8/dist-packages/gunicorn/app/base.py", line 228, in run
    super().run()
  File "/usr/local/lib/python3.8/dist-packages/gunicorn/app/base.py", line 72, in run
    Arbiter(self).run()
  File "/usr/local/lib/python3.8/dist-packages/gunicorn/arbiter.py", line 229, in run
    self.halt(reason=inst.reason, exit_status=inst.exit_status)
  File "/usr/local/lib/python3.8/dist-packages/gunicorn/arbiter.py", line 342, in halt
    self.stop()
  File "/usr/local/lib/python3.8/dist-packages/gunicorn/arbiter.py", line 393, in stop
    time.sleep(0.1)
  File "/usr/local/lib/python3.8/dist-packages/gunicorn/arbiter.py", line 242, in handle_chld
    self.reap_workers()
  File "/usr/local/lib/python3.8/dist-packages/gunicorn/arbiter.py", line 525, in reap_workers
    raise HaltServer(reason, self.WORKER_BOOT_ERROR)
gunicorn.errors.HaltServer: <HaltServer 'Worker failed to boot.' 3>
[2020-09-18 18:20:02 +0000] [1] [INFO] Starting gunicorn 20.0.4
[2020-09-18 18:20:02 +0000] [1] [INFO] Listening at: http://0.0.0.0:5000 (1)
[2020-09-18 18:20:02 +0000] [1] [INFO] Using worker: gevent
[2020-09-18 18:20:02 +0000] [7] [INFO] Booting worker with pid: 7
[2020-09-18 18:20:02 +0000] [8] [INFO] Booting worker with pid: 8
[2020-09-18 18:20:02 +0000] [9] [INFO] Booting worker with pid: 9
[2020-09-18 18:20:04 +0000] [1] [INFO] Shutting down: Master
[2020-09-18 18:20:04 +0000] [1] [INFO] Reason: Worker failed to boot.
[2020-09-18 18:26:22 +0000] [1] [INFO] Starting gunicorn 20.0.4
[2020-09-18 18:26:22 +0000] [1] [INFO] Listening at: http://0.0.0.0:5000 (1)
[2020-09-18 18:26:22 +0000] [1] [INFO] Using worker: gevent
[2020-09-18 18:26:22 +0000] [7] [INFO] Booting worker with pid: 7
[2020-09-18 18:26:22 +0000] [8] [INFO] Booting worker with pid: 8
[2020-09-18 18:26:22 +0000] [9] [INFO] Booting worker with pid: 9
[2020-09-18 18:26:24 +0000] [1] [INFO] Shutting down: Master
[2020-09-18 18:26:24 +0000] [1] [INFO] Reason: Worker failed to boot.
[2020-09-18 18:28:06 +0000] [1] [INFO] Starting gunicorn 20.0.4
[2020-09-18 18:28:06 +0000] [1] [INFO] Listening at: http://0.0.0.0:5000 (1)
[2020-09-18 18:28:06 +0000] [1] [INFO] Using worker: gevent
[2020-09-18 18:28:06 +0000] [8] [INFO] Booting worker with pid: 8
[2020-09-18 18:28:06 +0000] [9] [INFO] Booting worker with pid: 9
[2020-09-18 18:28:06 +0000] [10] [INFO] Booting worker with pid: 10
[2020-09-18 21:23:55 +0000] [1] [CRITICAL] WORKER TIMEOUT (pid:8)
[2020-09-18 21:23:56 +0000] [14] [INFO] Booting worker with pid: 14
[2020-09-19 03:24:05 +0000] [1] [CRITICAL] WORKER TIMEOUT (pid:9)
[2020-09-19 03:24:07 +0000] [16] [INFO] Booting worker with pid: 16
[2020-09-19 03:45:11 +0000] [1] [CRITICAL] WORKER TIMEOUT (pid:14)
[2020-09-19 03:45:23 +0000] [18] [INFO] Booting worker with pid: 18
[2020-09-19 04:46:20 +0000] [1] [CRITICAL] WORKER TIMEOUT (pid:18)
[2020-09-19 04:46:20 +0000] [18] [INFO] Worker exiting (pid: 18)
[2020-09-19 04:46:20 +0000] [19] [INFO] Booting worker with pid: 19
[2020-09-19 05:05:24 +0000] [1] [INFO] Handling signal: term
[2020-09-19 05:05:26 +0000] [1] [INFO] Shutting down: Master
[2020-09-19 05:05:33 +0000] [1] [INFO] Starting gunicorn 20.0.4
[2020-09-19 05:05:33 +0000] [1] [INFO] Listening at: http://0.0.0.0:5000 (1)
[2020-09-19 05:05:33 +0000] [1] [INFO] Using worker: gevent
[2020-09-19 05:05:33 +0000] [7] [INFO] Booting worker with pid: 7
[2020-09-19 05:05:33 +0000] [8] [INFO] Booting worker with pid: 8
[2020-09-19 05:05:33 +0000] [9] [INFO] Booting worker with pid: 9
[2020-09-19 05:06:02 +0000] [1] [INFO] Handling signal: term
[2020-09-19 05:06:03 +0000] [1] [INFO] Shutting down: Master
[2020-09-19 05:06:08 +0000] [1] [INFO] Starting gunicorn 20.0.4
[2020-09-19 05:06:08 +0000] [1] [INFO] Listening at: http://0.0.0.0:5000 (1)
[2020-09-19 05:06:08 +0000] [1] [INFO] Using worker: gevent
[2020-09-19 05:06:08 +0000] [8] [INFO] Booting worker with pid: 8
[2020-09-19 05:06:08 +0000] [9] [INFO] Booting worker with pid: 9
[2020-09-19 05:06:08 +0000] [10] [INFO] Booting worker with pid: 10
